Workbook
Name Slicer_Representative: #N/A

Sheet Data
B1: Call Centre Data
B3: Call number | C3: Customer ID | D3: Duration | E3: Representative | F3: Date of Call | G3: Purchase Amount | H3: Satisfaction Rating | I3: FY | J3: Day of week | K3: Duration Bucket | L3: Rating rounded | Q3: Customer ID | R3: Gedner | S3: Age | T3: City
B4: Call_7271 | C4: C0003 | D4: 116 | E4: R05 | F4: 44927 | G4: 128 | H4: 4.9 | I4: =IF(MONTH(calls[[#This Row],[Date of Call]])<=6, YEAR(calls[[#This Row],[Date of Call]]), YEAR(calls[[#This Row],[Date of Call]])+1) -> 2023 | J4: =TEXT(calls[[#This Row],[Date of Call]],"DDDD") -> Sunday | K4: {=_xlfn.IFS(calls[[#This Row],[Duration]]<=10,"Under 10 mins", calls[[#This Row],[Duration]]<=30, "10 to 30 mins", calls[[#This Row],[Duration]]<=60, "30 to 60 mins", calls[[#This Row],[Duration]]<=120, "1 to 2 hours", TRUE, "More than 2 hours")} -> 1 to 2 hours | L4: =ROUND(calls[[#This Row],[Satisfaction Rating]],0) -> 5 | Q4: C0001 | R4: Male | S4: 41 | T4: Columbus
B5: Call_7272 | C5: C0004 | D5: 119 | E5: R05 | F5: 44927 | G5: 135 | H5: 2.9 | I5: =IF(MONTH(calls[[#This Row],[Date of Call]])<=6, YEAR(calls[[#This Row],[Date of Call]]), YEAR(calls[[#This Row],[Date of Call]])+1) -> 2023 | J5: =TEXT(calls[[#This Row],[Date of Call]],"DDDD") -> Sunday | K5: {=_xlfn.IFS(calls[[#This Row],[Duration]]<=10,"Under 10 mins", calls[[#This Row],[Duration]]<=30, "10 to 30 mins", calls[[#This Row],[Duration]]<=60, "30 to 60 mins", calls[[#This Row],[Duration]]<=120, "1 to 2 hours", TRUE, "More than 2 hours")} -> 1 to 2 hours | L5: =ROUND(calls[[#This Row],[Satisfaction Rating]],0) -> 3 | Q5: C0002 | R5: Male | S5: 31 | T5: Cleveland
B6: Call_7273 | C6: C0005 | D6: 68 | E6: R02 | F6: 44927 | G6: 66 | H6: 4.7 | I6: =IF(MONTH(calls[[#This Row],[Date of Call]])<=6, YEAR(calls[[#This Row],[Date of Call]]), YEAR(calls[[#This Row],[Date of Call]])+1) -> 2023 | J6: =TEXT(calls[[#This Row],[Date of Call]],"DDDD") -> Sunday | K6: {=_xlfn.IFS(calls[[#This Row],[Duration]]<=10,"Under 10 mins", calls[[#This Row],[Duration]]<=30, "10 to 30 mins", calls[[#This Row],[Duration]]<=60, "30 to 60 mins", calls[[#This Row],[Duration]]<=120, "1 to 2 hours", TRUE, "More than 2 hours")} -> 1 to 2 hours | L6: =ROUND(calls[[#This Row],[Satisfaction Rating]],0) -> 5 | Q6: C0003 | R6: Male | S6: 26 | T6: Cincinnati
B7: Call_7274 | C7: C0014 | D7: 119 | E7: R02 | F7: 44927 | G7: 22 | H7: 2.9 | I7: =IF(MONTH(calls[[#This Row],[Date of Call]])<=6, YEAR(calls[[#This Row],[Date of Call]]), YEAR(calls[[#This Row],[Date of Call]])+1) -> 2023 | J7: =TEXT(calls[[#This Row],[Date of Call]],"DDDD") -> Sunday | K7: {=_xlfn.IFS(calls[[#This Row],[Duration]]<=10,"Under 10 mins", calls[[#This Row],[Duration]]<=30, "10 to 30 mins", calls[[#This Row],[Duration]]<=60, "30 to 60 mins", calls[[#This Row],[Duration]]<=120, "1 to 2 hours", TRUE, "More than 2 hours")} -> 1 to 2 hours | L7: =ROUND(calls[[#This Row],[Satisfaction Rating]],0) -> 3 | Q7: C0004 | R7: Male | S7: 36 | T7: Cincinnati
B8: Call_7275 | C8: C0011 | D8: 128 | E8: R01 | F8: 44928 | G8: 31 | H8: 2.8 | I8: =IF(MONTH(calls[[#This Row],[Date of Call]])<=6, YEAR(calls[[#This Row],[Date of Call]]), YEAR(calls[[#This Row],[Date of Call]])+1) -> 2023 | J8: =TEXT(calls[[#This Row],[Date of Call]],"DDDD") -> Monday | K8: {=_xlfn.IFS(calls[[#This Row],[Duration]]<=10,"Under 10 mins", calls[[#This Row],[Duration]]<=30, "10 to 30 mins", calls[[#This Row],[Duration]]<=60, "30 to 60 mins", calls[[#This Row],[Duration]]<=120, "1 to 2 hours", TRUE, "More than 2 hours")} -> More than 2 hours | L8: =ROUND(calls[[#This Row],[Satisfaction Rating]],0) -> 3 | Q8: C0005 | R8: Male | S8: 37 | T8: Columbus
B9: Call_7276 | C9: C0011 | D9: 49 | E9: R02 | F9: 44929 | G9: 135 | H9: 4.8 | I9: =IF(MONTH(calls[[#This Row],[Date of Call]])<=6, YEAR(calls[[#This Row],[Date of Call]]), YEAR(calls[[#This Row],[Date of Call]])+1) -> 2023 | J9: =TEXT(calls[[#This Row],[Date of Call]],"DDDD") -> Tuesday | K9: {=_xlfn.IFS(calls[[#This Row],[Duration]]<=10,"Under 10 mins", calls[[#This Row],[Duration]]<=30, "10 to 30 mins", calls[[#This Row],[Duration]]<=60, "30 to 60 mins", calls[[#This Row],[Duration]]<=120, "1 to 2 hours", TRUE, "More than 2 hours")} -> 30 to 60 mins | L9: =ROUND(calls[[#This Row],[Satisfaction Rating]],0) -> 5 | Q9: C0006 | R9: Male | S9: 23 | T9: Columbus
B10: Call_7277 | C10: C0007 | D10: 84 | E10: R05 | F10: 44929 | G10: 60 | H10: 4.7 | I10: =IF(MONTH(calls[[#This Row],[Date of Call]])<=6, YEAR(calls[[#This Row],[Date of Call]]), YEAR(calls[[#This Row],[Date of Call]])+1) -> 2023 | J10: =TEXT(calls[[#This Row],[Date of Call]],"DDDD") -> Tuesday | K10: {=_xlfn.IFS(calls[[#This Row],[Duration]]<=10,"Under 10 mins", calls[[#This Row],[Duration]]<=30, "10 to 30 mins", calls[[#This Row],[Duration]]<=60, "30 to 60 mins", calls[[#This Row],[Duration]]<=120, "1 to 2 hours", TRUE, "More than 2 hours")} -> 1 to 2 hours | L10: =ROUND(calls[[#This Row],[Satisfaction Rating]],0) -> 5 | Q10: C0007 | R10: Female | S10: 22 | T10: Cleveland
B11: Call_7278 | C11: C0003 | D11: 103 | E11: R04 | F11: 44929 | G11: 148 | H11: 4.4 | I11: =IF(MONTH(calls[[#This Row],[Date of Call]])<=6, YEAR(calls[[#This Row],[Date of Call]]), YEAR(calls[[#This Row],[Date of Call]])+1) -> 2023 | J11: =TEXT(calls[[#This Row],[Date of Call]],"DDDD") -> Tuesday | K11: {=_xlfn.IFS(calls[[#This Row],[Duration]]<=10,"Under 10 mins", calls[[#This Row],[Duration]]<=30, "10 to 30 mins", calls[[#This Row],[Duration]]<=60, "30 to 60 mins", calls[[#This Row],[Duration]]<=120, "1 to 2 hours", TRUE, "More than 2 hours")} -> 1 to 2 hours | L11: =ROUND(calls[[#This Row],[Satisfaction Rating]],0) -> 4 | Q11: C0008 | R11: Female | S11: 42 | T11: Cleveland
B12: Call_7279 | C12: C0005 | D12: 31 | E12: R02 | F12: 44929 | G12: 135 | H12: 3.6 | I12: =IF(MONTH(calls[[#This Row],[Date of Call]])<=6, YEAR(calls[[#This Row],[Date of Call]]), YEAR(calls[[#This Row],[Date of Call]])+1) -> 2023 | J12: =TEXT(calls[[#This Row],[Date of Call]],"DDDD") -> Tuesday | K12: {=_xlfn.IFS(calls[[#This Row],[Duration]]<=10,"Under 10 mins", calls[[#This Row],[Duration]]<=30, "10 to 30 mins", calls[[#This Row],[Duration]]<=60, "30 to 60 mins", calls[[#This Row],[Duration]]<=120, "1 to 2 hours", TRUE, "More than 2 hours")} -> 30 to 60 mins | L12: =ROUND(calls[[#This Row],[Satisfaction Rating]],0) -> 4 | Q12: C0009 | R12: Female | S12: 25 | T12: Columbus
B13: Call_7280 | C13: C0010 | D13: 44 | E13: R03 | F13: 44929 | G13: 105 | H13: 2.9 | I13: =IF(MONTH(calls[[#This Row],[Date of Call]])<=6, YEAR(calls[[#This Row],[Date of Call]]), YEAR(calls[[#This Row],[Date of Call]])+1) -> 2023 | J13: =TEXT(calls[[#This Row],[Date of Call]],"DDDD") -> Tuesday | K13: {=_xlfn.IFS(calls[[#This Row],[Duration]]<=10,"Under 10 mins", calls[[#This Row],[Duration]]<=30, "10 to 30 mins", calls[[#This Row],[Duration]]<=60, "30 to 60 mins", calls[[#This Row],[Duration]]<=120, "1 to 2 hours", TRUE, "More than 2 hours")} -> 30 to 60 mins | L13: =ROUND(calls[[#This Row],[Satisfaction Rating]],0) -> 3 | Q13: C0010 | R13: Female | S13: 30 | T13: Cleveland
B14: Call_7281 | C14: C0011 | D14: 102 | E14: R02 | F14: 44929 | G14: 69 | H14: 4.9 | I14: =IF(MONTH(calls[[#This Row],[Date of Call]])<=6, YEAR(calls[[#This Row],[Date of Call]]), YEAR(calls[[#This Row],[Date of Call]])+1) -> 2023 | J14: =TEXT(calls[[#This Row],[Date of Call]],"DDDD") -> Tuesday | K14: {=_xlfn.IFS(calls[[#This Row],[Duration]]<=10,"Under 10 mins", calls[[#This Row],[Duration]]<=30, "10 to 30 mins", calls[[#This Row],[Duration]]<=60, "30 to 60 mins", calls[[#This Row],[Duration]]<=120, "1 to 2 hours", TRUE, "More than 2 hours")} -> 1 to 2 hours | L14: =ROUND(calls[[#This Row],[Satisfaction Rating]],0) -> 5 | Q14: C0011 | R14: Female | S14: 30 | T14: Cincinnati
B15: Call_7282 | C15: C0013 | D15: 135 | E15: R05 | F15: 44929 | G15: 46 | H15: 3.4 | I15: =IF(MONTH(calls[[#This Row],[Date of Call]])<=6, YEAR(calls[[#This Row],[Date of Call]]), YEAR(calls[[#This Row],[Date of Call]])+1) -> 2023 | J15: =TEXT(calls[[#This Row],[Date of Call]],"DDDD") -> Tuesday | K15: {=_xlfn.IFS(calls[[#This Row],[Duration]]<=10,"Under 10 mins", calls[[#This Row],[Duration]]<=30, "10 to 30 mins", calls[[#This Row],[Duration]]<=60, "30 to 60 mins", calls[[#This Row],[Duration]]<=120, "1 to 2 hours", TRUE, "More than 2 hours")} -> More than 2 hours | L15: =ROUND(calls[[#This Row],[Satisfaction Rating]],0) -> 3 | Q15: C0012 | R15: Female | S15: 28 | T15: Cincinnati
... B18: Call_7285 | C18: C0013 | D18: 48 | E18: R01 | F18: 44930 | G18: 68 | H18: 4.9 | I18: =IF(MONTH(calls[[#This Row],[Date of Call]])<=6, YEAR(calls[[#This Row],[Date of Call]]), YEAR(calls[[#This Row],[Date of Call]])+1) -> 2023 | J18: =TEXT(calls[[#This Row],[Date of Call]],"DDDD") -> Wednesday | K18: {=_xlfn.IFS(calls[[#This Row],[Duration]]<=10,"Under 10 mins", calls[[#This Row],[Duration]]<=30, "10 to 30 mins", calls[[#This Row],[Duration]]<=60, "30 to 60 mins", calls[[#This Row],[Duration]]<=120, "1 to 2 hours", TRUE, "More than 2 hours")} -> 30 to 60 mins | L18: =ROUND(calls[[#This Row],[Satisfaction Rating]],0) -> 5 | Q18: C0015 | R18: Female | S18: 43 | T18: Cleveland
B19: Call_7286 | C19: C0010 | D19: 176 | E19: R05 | F19: 44931 | G19: 24 | H19: 4.8 | I19: =IF(MONTH(calls[[#This Row],[Date of Call]])<=6, YEAR(calls[[#This Row],[Date of Call]]), YEAR(calls[[#This Row],[Date of Call]])+1) -> 2023 | J19: =TEXT(calls[[#This Row],[Date of Call]],"DDDD") -> Thursday | K19: {=_xlfn.IFS(calls[[#This Row],[Duration]]<=10,"Under 10 mins", calls[[#This Row],[Duration]]<=30, "10 to 30 mins", calls[[#This Row],[Duration]]<=60, "30 to 60 mins", calls[[#This Row],[Duration]]<=120, "1 to 2 hours", TRUE, "More than 2 hours")} -> More than 2 hours | L19: =ROUND(calls[[#This Row],[Satisfaction Rating]],0) -> 5
B20: Call_7287 | C20: C0010 | D20: 99 | E20: R01 | F20: 44931 | G20: 195 | H20: 3.9 | I20: =IF(MONTH(calls[[#This Row],[Date of Call]])<=6, YEAR(calls[[#This Row],[Date of Call]]), YEAR(calls[[#This Row],[Date of Call]])+1) -> 2023 | J20: =TEXT(calls[[#This Row],[Date of Call]],"DDDD") -> Thursday | K20: {=_xlfn.IFS(calls[[#This Row],[Duration]]<=10,"Under 10 mins", calls[[#This Row],[Duration]]<=30, "10 to 30 mins", calls[[#This Row],[Duration]]<=60, "30 to 60 mins", calls[[#This Row],[Duration]]<=120, "1 to 2 hours", TRUE, "More than 2 hours")} -> 1 to 2 hours | L20: =ROUND(calls[[#This Row],[Satisfaction Rating]],0) -> 4
B21: Call_7288 | C21: C0009 | D21: 28 | E21: R03 | F21: 44931 | G21: 28 | H21: 3.8 | I21: =IF(MONTH(calls[[#This Row],[Date of Call]])<=6, YEAR(calls[[#This Row],[Date of Call]]), YEAR(calls[[#This Row],[Date of Call]])+1) -> 2023 | J21: =TEXT(calls[[#This Row],[Date of Call]],"DDDD") -> Thursday | K21: {=_xlfn.IFS(calls[[#This Row],[Duration]]<=10,"Under 10 mins", calls[[#This Row],[Duration]]<=30, "10 to 30 mins", calls[[#This Row],[Duration]]<=60, "30 to 60 mins", calls[[#This Row],[Duration]]<=120, "1 to 2 hours", TRUE, "More than 2 hours")} -> 10 to 30 mins | L21: =ROUND(calls[[#This Row],[Satisfaction Rating]],0) -> 4
B22: Call_7289 | C22: C0007 | D22: 54 | E22: R02 | F22: 44931 | G22: 170 | H22: 4.3 | I22: =IF(MONTH(calls[[#This Row],[Date of Call]])<=6, YEAR(calls[[#This Row],[Date of Call]]), YEAR(calls[[#This Row],[Date of Call]])+1) -> 2023 | J22: =TEXT(calls[[#This Row],[Date of Call]],"DDDD") -> Thursday | K22: {=_xlfn.IFS(calls[[#This Row],[Duration]]<=10,"Under 10 mins", calls[[#This Row],[Duration]]<=30, "10 to 30 mins", calls[[#This Row],[Duration]]<=60, "30 to 60 mins", calls[[#This Row],[Duration]]<=120, "1 to 2 hours", TRUE, "More than 2 hours")} -> 30 to 60 mins | L22: =ROUND(calls[[#This Row],[Satisfaction Rating]],0) -> 4
B23: Call_7290 | C23: C0006 | D23: 48 | E23: R05 | F23: 44932 | G23: 30 | H23: 4.4 | I23: =IF(MONTH(calls[[#This Row],[Date of Call]])<=6, YEAR(calls[[#This Row],[Date of Call]]), YEAR(calls[[#This Row],[Date of Call]])+1) -> 2023 | J23: =TEXT(calls[[#This Row],[Date of Call]],"DDDD") -> Friday | K23: {=_xlfn.IFS(calls[[#This Row],[Duration]]<=10,"Under 10 mins", calls[[#This Row],[Duration]]<=30, "10 to 30 mins", calls[[#This Row],[Duration]]<=60, "30 to 60 mins", calls[[#This Row],[Duration]]<=120, "1 to 2 hours", TRUE, "More than 2 hours")} -> 30 to 60 mins | L23: =ROUND(calls[[#This Row],[Satisfaction Rating]],0) -> 4
B24: Call_7291 | C24: C0004 | D24: 128 | E24: R05 | F24: 44932 | G24: 72 | H24: 5 | I24: =IF(MONTH(calls[[#This Row],[Date of Call]])<=6, YEAR(calls[[#This Row],[Date of Call]]), YEAR(calls[[#This Row],[Date of Call]])+1) -> 2023 | J24: =TEXT(calls[[#This Row],[Date of Call]],"DDDD") -> Friday | K24: {=_xlfn.IFS(calls[[#This Row],[Duration]]<=10,"Under 10 mins", calls[[#This Row],[Duration]]<=30, "10 to 30 mins", calls[[#This Row],[Duration]]<=60, "30 to 60 mins", calls[[#This Row],[Duration]]<=120, "1 to 2 hours", TRUE, "More than 2 hours")} -> More than 2 hours | L24: =ROUND(calls[[#This Row],[Satisfaction Rating]],0) -> 5
B25: Call_7292 | C25: C0004 | D25: 38 | E25: R04 | F25: 44933 | G25: 92 | H25: 4.9 | I25: =IF(MONTH(calls[[#This Row],[Date of Call]])<=6, YEAR(calls[[#This Row],[Date of Call]]), YEAR(calls[[#This Row],[Date of Call]])+1) -> 2023 | J25: =TEXT(calls[[#This Row],[Date of Call]],"DDDD") -> Saturday | K25: {=_xlfn.IFS(calls[[#This Row],[Duration]]<=10,"Under 10 mins", calls[[#This Row],[Duration]]<=30, "10 to 30 mins", calls[[#This Row],[Duration]]<=60, "30 to 60 mins", calls[[#This Row],[Duration]]<=120, "1 to 2 hours", TRUE, "More than 2 hours")} -> 30 to 60 mins | L25: =ROUND(calls[[#This Row],[Satisfaction Rating]],0) -> 5
B26: Call_7293 | C26: C0003 | D26: 67 | E26: R04 | F26: 44934 | G26: 165 | H26: 4.5 | I26: =IF(MONTH(calls[[#This Row],[Date of Call]])<=6, YEAR(calls[[#This Row],[Date of Call]]), YEAR(calls[[#This Row],[Date of Call]])+1) -> 2023 | J26: =TEXT(calls[[#This Row],[Date of Call]],"DDDD") -> Sunday | K26: {=_xlfn.IFS(calls[[#This Row],[Duration]]<=10,"Under 10 mins", calls[[#This Row],[Duration]]<=30, "10 to 30 mins", calls[[#This Row],[Duration]]<=60, "30 to 60 mins", calls[[#This Row],[Duration]]<=120, "1 to 2 hours", TRUE, "More than 2 hours")} -> 1 to 2 hours | L26: =ROUND(calls[[#This Row],[Satisfaction Rating]],0) -> 5
B27: Call_7294 | C27: C0015 | D27: 58 | E27: R02 | F27: 44934 | G27: 140 | H27: 2.1 | I27: =IF(MONTH(calls[[#This Row],[Date of Call]])<=6, YEAR(calls[[#This Row],[Date of Call]]), YEAR(calls[[#This Row],[Date of Call]])+1) -> 2023 | J27: =TEXT(calls[[#This Row],[Date of Call]],"DDDD") -> Sunday | K27: {=_xlfn.IFS(calls[[#This Row],[Duration]]<=10,"Under 10 mins", calls[[#This Row],[Duration]]<=30, "10 to 30 mins", calls[[#This Row],[Duration]]<=60, "30 to 60 mins", calls[[#This Row],[Duration]]<=120, "1 to 2 hours", TRUE, "More than 2 hours")} -> 30 to 60 mins | L27: =ROUND(calls[[#This Row],[Satisfaction Rating]],0) -> 2
B28: Call_7295 | C28: C0010 | D28: 54 | E28: R01 | F28: 44934 | G28: 111 | H28: 3.3 | I28: =IF(MONTH(calls[[#This Row],[Date of Call]])<=6, YEAR(calls[[#This Row],[Date of Call]]), YEAR(calls[[#This Row],[Date of Call]])+1) -> 2023 | J28: =TEXT(calls[[#This Row],[Date of Call]],"DDDD") -> Sunday | K28: {=_xlfn.IFS(calls[[#This Row],[Duration]]<=10,"Under 10 mins", calls[[#This Row],[Duration]]<=30, "10 to 30 mins", calls[[#This Row],[Duration]]<=60, "30 to 60 mins", calls[[#This Row],[Duration]]<=120, "1 to 2 hours", TRUE, "More than 2 hours")} -> 30 to 60 mins | L28: =ROUND(calls[[#This Row],[Satisfaction Rating]],0) -> 3
B29: Call_7296 | C29: C0012 | D29: 28 | E29: R05 | F29: 44935 | G29: 63 | H29: 4.1 | I29: =IF(MONTH(calls[[#This Row],[Date of Call]])<=6, YEAR(calls[[#This Row],[Date of Call]]), YEAR(calls[[#This Row],[Date of Call]])+1) -> 2023 | J29: =TEXT(calls[[#This Row],[Date of Call]],"DDDD") -> Monday | K29: {=_xlfn.IFS(calls[[#This Row],[Duration]]<=10,"Under 10 mins", calls[[#This Row],[Duration]]<=30, "10 to 30 mins", calls[[#This Row],[Duration]]<=60, "30 to 60 mins", calls[[#This Row],[Duration]]<=120, "1 to 2 hours", TRUE, "More than 2 hours")} -> 10 to 30 mins | L29: =ROUND(calls[[#This Row],[Satisfaction Rating]],0) -> 4
B30: Call_7297 | C30: C0002 | D30: 73 | E30: R05 | F30: 44935 | G30: 80 | H30: 4.2 | I30: =IF(MONTH(calls[[#This Row],[Date of Call]])<=6, YEAR(calls[[#This Row],[Date of Call]]), YEAR(calls[[#This Row],[Date of Call]])+1) -> 2023 | J30: =TEXT(calls[[#This Row],[Date of Call]],"DDDD") -> Monday | K30: {=_xlfn.IFS(calls[[#This Row],[Duration]]<=10,"Under 10 mins", calls[[#This Row],[Duration]]<=30, "10 to 30 mins", calls[[#This Row],[Duration]]<=60, "30 to 60 mins", calls[[#This Row],[Duration]]<=120, "1 to 2 hours", TRUE, "More than 2 hours")} -> 1 to 2 hours | L30: =ROUND(calls[[#This Row],[Satisfaction Rating]],0) -> 4
... B1003: Call_8270 | C1003: C0009 | D1003: 114 | E1003: R01 | F1003: 45291 | G1003: 40 | H1003: 3.9 | I1003: =IF(MONTH(calls[[#This Row],[Date of Call]])<=6, YEAR(calls[[#This Row],[Date of Call]]), YEAR(calls[[#This Row],[Date of Call]])+1) -> 2024 | J1003: =TEXT(calls[[#This Row],[Date of Call]],"DDDD") -> Sunday | K1003: {=_xlfn.IFS(calls[[#This Row],[Duration]]<=10,"Under 10 mins", calls[[#This Row],[Duration]]<=30, "10 to 30 mins", calls[[#This Row],[Duration]]<=60, "30 to 60 mins", calls[[#This Row],[Duration]]<=120, "1 to 2 hours", TRUE, "More than 2 hours")} -> 1 to 2 hours | L1003: =ROUND(calls[[#This Row],[Satisfaction Rating]],0) -> 4

Sheet Assets
E2: Rep ID
E3: R01
E4: R02 | H4: Step-1 | I4: Set up the dshboard page and Theme
E5: R03 | H5: Step-2 | I5: Report generation building Pivots for the KIPs
E6: R04 | H6: Step-3 | I6: Creating the data model
E7: R05 | I7: For this we need to combine the calls table with the customer table using pivot able
I8: Go to the pivot analyse ribbon and set up relation between both by using the Customer ID option
H9: Step-4 | I9: Using DAX Measures-it activates when u use relationship table and data models,this is the calculation not in the table but on top of it for us to drive extra summary.
I10: Go to the Calls table icon in pivot and choose add measures
I11: Use DAX(Data Analyses Expressions) syntax i.e COUNTROWS(CALLS)
I12: This will give total calls in numbers
H13: Step-5 | I13: Using DAX Measures
I14: Go to the Calls table icon in pivot and choose add measures
I15: this time name it as Total amount write the DAX sytax i.e SUM(calls[Purchase amount])
I16: Select currency option and click ok.
H17: Step-6 | I17: Similary add Total Duration in pivot option using DAX
H18: Step-7 | I18: Similary add Avg Rating in pivot option using DAX
H19: Step-8 | I19: Now adding measure of most happy customers having 5*calls
I20: CALCULATE([Call Count],calls[Rating rounded]=5
H21: Step-9 | I21: we got the summary of the data so name it as Summary pivot
H22: Step-10 | I22: Now using the summary pivot we need to check how the data changes according to each REP
I23: So we copy that pivot and paste as REP pivot and now add Representative as A Slicer
H24: Step-11 | I24: Design the Report sheet by adding shapes shadows
I25: to adjust shadows and shape use ctrl+1
H26: Step-12 | I26: select the box and go to header to write = and get the value in your box
I27: Now select the call count number from the pivot for it to be shown in the coloure box then hit enter
I28: but there is error that GETPIVOTDATA
I29: Now we have to disable it so that the fumction could work
I30: Go to Pivot analyze ribbon and go to options and disabel generate get pivot option
H31: Step-13 | I31: for copying same tpe of boxes got to home ribbon
I32: select find & select option-select objects
H33: Step-14 | I33: select the whole box
I34: then ctrl C
I35: Then esc key
I36: then paste down
H37: Step-15 | I37: Build trend graph

Sheet customer centre report
C1: CALL CENTRE REPORT
R13: R01 | S13: R02 | T13: R03 | U13: R04 | V13: R05 | W13: TOTAL
Q14: =PIVOT!A63 -> Cincinnati
Q15: =PIVOT!A64 -> C0003 | R15: =PIVOT!B64 -> 891 | S15: =PIVOT!C64 -> 1332 | T15: =PIVOT!D64 -> 1282 | U15: =PIVOT!E64 -> 739 | V15: =PIVOT!F64 -> 560 | W15: =PIVOT!G64 -> 4804
Q16: =PIVOT!A65 -> C0004 | R16: =PIVOT!B65 -> 1991 | S16: =PIVOT!C65 -> 1886 | T16: =PIVOT!D65 -> 1206 | U16: =PIVOT!E65 -> 884 | V16: =PIVOT!F65 -> 1722 | W16: =PIVOT!G65 -> 7689
Q17: =PIVOT!A66 -> C0011 | R17: =PIVOT!B66 -> 1163 | S17: =PIVOT!C66 -> 1180 | T17: =PIVOT!D66 -> 1616 | U17: =PIVOT!E66 -> 1043 | V17: =PIVOT!F66 -> 1747 | W17: =PIVOT!G66 -> 6749
Q18: =PIVOT!A67 -> C0012 | R18: =PIVOT!B67 -> 1438 | S18: =PIVOT!C67 -> 1616 | T18: =PIVOT!D67 -> 866 | U18: =PIVOT!E67 -> 829 | V18: =PIVOT!F67 -> 2070 | W18: =PIVOT!G67 -> 6819
Q19: =PIVOT!A68 -> Cleveland
Q20: =PIVOT!A69 -> C0002 | R20: =PIVOT!B69 -> 1233 | S20: =PIVOT!C69 -> 223 | T20: =PIVOT!D69 -> 1680 | U20: =PIVOT!E69 -> 990 | V20: =PIVOT!F69 -> 1508 | W20: =PIVOT!G69 -> 5634
Q21: =PIVOT!A70 -> C0007 | R21: =PIVOT!B70 -> 1598 | S21: =PIVOT!C70 -> 1907 | T21: =PIVOT!D70 -> 869 | U21: =PIVOT!E70 -> 1426 | V21: =PIVOT!F70 -> 1416 | W21: =PIVOT!G70 -> 7216
Q22: =PIVOT!A71 -> C0008 | R22: =PIVOT!B71 -> 900 | S22: =PIVOT!C71 -> 1016 | T22: =PIVOT!D71 -> 960 | U22: =PIVOT!E71 -> 940 | V22: =PIVOT!F71 -> 1193 | W22: =PIVOT!G71 -> 5009
Q23: =PIVOT!A72 -> C0010 | R23: =PIVOT!B72 -> 900 | S23: =PIVOT!C72 -> 1470 | T23: =PIVOT!D72 -> 1617 | U23: =PIVOT!E72 -> 1314 | V23: =PIVOT!F72 -> 941 | W23: =PIVOT!G72 -> 6242
Q24: =PIVOT!A73 -> C0013 | R24: =PIVOT!B73 -> 1255 | S24: =PIVOT!C73 -> 516 | T24: =PIVOT!D73 -> 1874 | U24: =PIVOT!E73 -> 1863 | V24: =PIVOT!F73 -> 1722 | W24: =PIVOT!G73 -> 7230
Q25: =PIVOT!A74 -> C0015 | R25: =PIVOT!B74 -> 1138 | S25: =PIVOT!C74 -> 1898 | T25: =PIVOT!D74 -> 1482 | U25: =PIVOT!E74 -> 846 | V25: =PIVOT!F74 -> 1154 | W25: =PIVOT!G74 -> 6518
Q26: =PIVOT!A75 -> Columbus
Q27: =PIVOT!A76 -> C0001 | R27: =PIVOT!B76 -> 1655 | S27: =PIVOT!C76 -> 805 | T27: =PIVOT!D76 -> 2263 | U27: =PIVOT!E76 -> 987 | V27: =PIVOT!F76 -> 1075 | W27: =PIVOT!G76 -> 6785
Q28: =PIVOT!A77 -> C0005 | R28: =PIVOT!B77 -> 1104 | S28: =PIVOT!C77 -> 2280 | T28: =PIVOT!D77 -> 1445 | U28: =PIVOT!E77 -> 1722 | V28: =PIVOT!F77 -> 1196 | W28: =PIVOT!G77 -> 7747
Q29: =PIVOT!A78 -> C0006 | R29: =PIVOT!B78 -> 372 | S29: =PIVOT!C78 -> 1818 | T29: =PIVOT!D78 -> 1346 | U29: =PIVOT!E78 -> 1156 | V29: =PIVOT!F78 -> 1484 | W29: =PIVOT!G78 -> 6176
Q30: =PIVOT!A79 -> C0009 | R30: =PIVOT!B79 -> 1415 | S30: =PIVOT!C79 -> 1271 | T30: =PIVOT!D79 -> 1214 | U30: =PIVOT!E79 -> 1135 | V30: =PIVOT!F79 -> 1566 | W30: =PIVOT!G79 -> 6601
Q31: =PIVOT!A80 -> C0014 | R31: =PIVOT!B80 -> 1362 | S31: =PIVOT!C80 -> 1363 | T31: =PIVOT!D80 -> 1152 | U31: =PIVOT!E80 -> 777 | V31: =PIVOT!F80 -> 750 | W31: =PIVOT!G80 -> 5404

Sheet PIVOT
A1: PIVOT 1
A3: Call Count | B3: Total Amount | C3: Total Duration | D3: Avg Ratings | E3: 5* Calls
A4: 1000 | B4: 96623 | C4: 89850 | D4: 3.8854 | E4: 307
A7: Call Count | B7: Total Amount | C7: Total Duration | D7: Avg Ratings | E7: 5* Calls | H7: This is connected with the REP Slicer
A8: 189 | B8: 18415 | C8: 16834 | D8: 3.9227513 | E8: 60
A10: PIVOT 2
A13: Row Labels | B13: Call Count | C13: Call Count2 | H13: This is connected with the REP Slicer
A14: Jan | B14: 16 | C14: 16 | G14: Row Labels | H14: Call Count
A15: Feb | B15: 14 | C15: 14 | G15: Monday | H15: 30
A16: Mar | B16: 26 | C16: 26 | G16: Tuesday | H16: 13
A17: Apr | B17: 29 | C17: 29 | G17: Wednesday | H17: 23
A18: May | B18: 17 | C18: 17 | G18: Thursday | H18: 23
A19: Jun | B19: 15 | C19: 15 | G19: Friday | H19: 24
A20: Jul | B20: 15 | C20: 15 | G20: Saturday | H20: 40
A21: Aug | B21: 7 | C21: 7 | G21: Sunday | H21: 36
A22: Sep | B22: 11 | C22: 11 | G22: Grand Total | H22: 189
A23: Oct | B23: 24 | C23: 24
A24: Nov | B24: 9 | C24: 9
A25: Dec | B25: 6 | C25: 6
A26: Grand Total | B26: 189 | C26: 189
E27: For graph | H27: Selected Rep | I27: =A40 -> R01
A29: Row Labels | B29: Call Count | C29: Total Amount | E29: Rep | F29: Calls | G29: Amount | H29: Sel.calls | I29: Sel.amount
A30: R01 | B30: 189 | C30: 18415 | E30: =A30 -> R01 | F30: =B30 -> 189 | G30: =C30 -> 18415 | H30: =IF(E30=$I$27,F30,NA()) -> 189 | I30: =IF(E30=$I$27,G30,NA()) -> 18415
A31: R02 | B31: 218 | C31: 20581 | E31: =A31 -> R02 | F31: =B31 -> 218 | G31: =C31 -> 20581 | H31: =IF(E31=$I$27,F31,NA()) -> #N/A | I31: =IF(E31=$I$27,G31,NA()) -> #N/A
A32: R03 | B32: 207 | C32: 20872 | E32: =A32 -> R03 | F32: =B32 -> 207 | G32: =C32 -> 20872 | H32: =IF(E32=$I$27,F32,NA()) -> #N/A | I32: =IF(E32=$I$27,G32,NA()) -> #N/A
A33: R04 | B33: 186 | C33: 16651 | E33: =A33 -> R04 | F33: =B33 -> 186 | G33: =C33 -> 16651 | H33: =IF(E33=$I$27,F33,NA()) -> #N/A | I33: =IF(E33=$I$27,G33,NA()) -> #N/A
A34: R05 | B34: 200 | C34: 20104 | E34: =A34 -> R05 | F34: =B34 -> 200 | G34: =C34 -> 20104 | H34: =IF(E34=$I$27,F34,NA()) -> #N/A | I34: =IF(E34=$I$27,G34,NA()) -> #N/A
A35: Grand Total | B35: 1000 | C35: 96623
A39: Row Labels
A40: R01
A43: Call Count | B43: Column Labels
A44: Row Labels | B44: Female | C44: Male | D44: Grand Total
A45: Cincinnati | B45: 144 | C45: 132 | D45: 276
A46: Cleveland | B46: 326 | C46: 63 | D46: 389
A47: Columbus | B47: 129 | C47: 206 | D47: 335
A48: Grand Total | B48: 599 | C48: 401 | D48: 1000
A51: Row Labels | B51: Call Count
A52: 1 | B52: 1
A53: 2 | B53: 9
A54: 3 | B54: 31
...
